<?xml version="1.0" ?>
<!-- =================================================================================== -->
<!-- |    This document was autogenerated by xacro from rbs_gripper.xacro              | -->
<!-- |    EDITING THIS FILE BY HAND IS NOT RECOMMENDED                                 | -->
<!-- =================================================================================== -->
<robot name="rbs-gripper">
  <link name="world"/>
  <ros2_control name="rbs-gripper_gazebo" type="system">
    <!-- Plugins -->
    <hardware>
      <plugin>gz_ros2_control/GazeboSimSystem</plugin>
    </hardware>
    <!-- Joint interfaces -->
    <joint name="rbs-gripper_rot_base_joint">
      <state_interface name="position">
        <param name="initial_value">0.000</param>
      </state_interface>
      <command_interface name="position"/>
      <command_interface name="velocity"/>
      <!-- <command_interface name="effort"/> -->
      <state_interface name="velocity"/>
      <state_interface name="effort"/>
    </joint>
    <joint name="rbs-gripper_r_finger_joint">
      <state_interface name="position">
        <param name="initial_value">0.004</param>
      </state_interface>
      <command_interface name="position"/>
      <command_interface name="velocity"/>
      <!-- <command_interface name="effort"/> -->
      <state_interface name="velocity"/>
      <state_interface name="effort"/>
    </joint>
    <joint name="rbs-gripper_l_finger_joint">
      <param name="mimic">rbs-gripper_r_finger_joint</param>
      <param name="multiplier">1</param>
    </joint>
  </ros2_control>
  <joint name="rbs-gripper_gripper_base_joint" type="fixed">
    <origin rpy="0 0 0" xyz="0 0 0"/>
    <parent link="world"/>
    <child link="rbs-gripper_gripper_base_link"/>
  </joint>
  <link name="rbs-gripper_gripper_base_link">
    <inertial>
      <origin rpy="0 0 0" xyz="0.000364704367134063 0.0336387482840125 0.0593891203954369"/>
      <mass value="1.13983632906086"/>
      <inertia ixx="0.00107738806534129" ixy="-1.09841172461737E-05" ixz="2.62750043451545E-06" iyy="0.000717388573992299" iyz="-2.95426438182787E-05" izz="0.00115777179755934"/>
    </inertial>
    <visual>
      <origin rpy="0 0 0" xyz="0 0 0"/>
      <geometry>
        <mesh filename="file:///home/narmak/rbs_ws/install/rbs_gripper/share/rbs_gripper/meshes/visual/base.dae"/>
      </geometry>
      <material name="rbs-gripper_material">
        <color rgba="0.752941176470588 0.752941176470588 0.752941176470588 1"/>
      </material>
    </visual>
    <collision>
      <origin rpy="0 0 0" xyz="0 0 0"/>
      <geometry>
        <mesh filename="file:///home/narmak/rbs_ws/install/rbs_gripper/share/rbs_gripper/meshes/collision/base.stl"/>
      </geometry>
    </collision>
  </link>
  <link name="rbs-gripper_rot_base_link">
    <inertial>
      <origin rpy="0 0 0" xyz="6.79110135283868E-11 -3.80956832067611E-10 0.00775394473595793"/>
      <mass value="0.161003401535982"/>
      <inertia ixx="0.00011089089949771" ixy="5.01335040610636E-06" ixz="1.74608448389267E-14" iyy="0.000105515893695012" iyz="-2.03282362854432E-14" izz="0.000206912001661452"/>
    </inertial>
    <visual>
      <origin rpy="0 0 0" xyz="0 0 0"/>
      <geometry>
        <mesh filename="file:///home/narmak/rbs_ws/install/rbs_gripper/share/rbs_gripper/meshes/visual/rotor.dae"/>
      </geometry>
      <material name="rbs-gripper_material">
        <color rgba="0.250980392156863 0.250980392156863 0.250980392156863 1"/>
      </material>
    </visual>
    <collision>
      <origin rpy="0 0 0" xyz="0 0 0"/>
      <geometry>
        <mesh filename="file:///home/narmak/rbs_ws/install/rbs_gripper/share/rbs_gripper/meshes/collision/rotor.stl"/>
      </geometry>
    </collision>
  </link>
  <joint name="rbs-gripper_rot_base_joint" type="revolute">
    <origin rpy="0 0 0" xyz="0 0 0.10861"/>
    <parent link="rbs-gripper_gripper_base_link"/>
    <child link="rbs-gripper_rot_base_link"/>
    <axis xyz="0 0 1"/>
    <limit effort="78" lower="-3.14159" upper="3.14159" velocity="0.52"/>
  </joint>
  <link name="rbs-gripper_l_finger_link">
    <inertial>
      <origin rpy="0 0 0" xyz="0.00399878118534129 0.0187296413885176 -0.0777776233934166"/>
      <mass value="0.0601996441483964"/>
      <inertia ixx="4.18533281165612E-05" ixy="-7.11657995951147E-06" ixz="1.81029223490065E-05" iyy="7.89886367868258E-05" iyz="1.20542845942065E-05" izz="5.16740841307935E-05"/>
    </inertial>
    <visual>
      <origin rpy="0 0 0" xyz="0 0 0"/>
      <geometry>
        <mesh filename="file:///home/narmak/rbs_ws/install/rbs_gripper/share/rbs_gripper/meshes/visual/finger.dae"/>
      </geometry>
      <material name="rbs-gripper_material">
        <color rgba="0.752941176470588 0 0 1"/>
      </material>
    </visual>
    <collision>
      <origin rpy="0 0 0" xyz="0 0 0"/>
      <geometry>
        <mesh filename="file:///home/narmak/rbs_ws/install/rbs_gripper/share/rbs_gripper/meshes/collision/finger.stl"/>
      </geometry>
    </collision>
  </link>
  <joint name="rbs-gripper_l_finger_joint" type="prismatic">
    <origin rpy="0 0 1.5708" xyz="0 0 0.1071"/>
    <parent link="rbs-gripper_rot_base_link"/>
    <child link="rbs-gripper_l_finger_link"/>
    <axis xyz="-1 0 0"/>
    <limit effort="10" lower="0" upper="0.064" velocity="0.53"/>
    <mimic joint="rbs-gripper_r_finger_joint" multiplier="1"/>
  </joint>
  <link name="rbs-gripper_r_finger_link">
    <inertial>
      <origin rpy="0 0 0" xyz="0.0039988 -0.077778 -0.01873"/>
      <mass value="0.0602"/>
      <inertia ixx="4.1853E-05" ixy="1.8103E-05" ixz="7.1166E-06" iyy="5.1674E-05" iyz="-1.2054E-05" izz="7.8989E-05"/>
    </inertial>
    <visual>
      <origin rpy="0 0 0" xyz="0 0 0"/>
      <geometry>
        <mesh filename="file:///home/narmak/rbs_ws/install/rbs_gripper/share/rbs_gripper/meshes/visual/finger.dae"/>
      </geometry>
      <material name="rbs-gripper_material">
        <color rgba="0.75294 0 0 1"/>
      </material>
    </visual>
    <collision>
      <origin rpy="0 0 0" xyz="0 0 0"/>
      <geometry>
        <mesh filename="file:///home/narmak/rbs_ws/install/rbs_gripper/share/rbs_gripper/meshes/collision/finger.stl"/>
      </geometry>
    </collision>
  </link>
  <joint name="rbs-gripper_r_finger_joint" type="prismatic">
    <origin rpy="0 0 -1.5708" xyz="0 0 0.1071"/>
    <parent link="rbs-gripper_rot_base_link"/>
    <child link="rbs-gripper_r_finger_link"/>
    <axis xyz="-1 0 0"/>
    <limit effort="10" lower="0" upper="0.064" velocity="0.53"/>
  </joint>
  <link name="gripper_grasp_point"/>
  <joint name="rbs-gripper_gripper_tool0_joint" type="fixed">
    <origin rpy="0 0 0" xyz="0 0 0.09139"/>
    <parent link="rbs-gripper_rot_base_link"/>
    <child link="gripper_grasp_point"/>
  </joint>
  <gazebo reference="rbs-gripper_rot_base_link">
    <self_collide>1</self_collide>
    <!-- <soft_contact> -->
    <!--   <dart> -->
    <!--     <bone_attachment>100</bone_attachment> -->
    <!--     <stiffness>100</stiffness> -->
    <!--     <damping>10</damping> -->
    <!--     <flesh_mass_fraction>0.050000000000000003</flesh_mass_fraction> -->
    <!--   </dart> -->
    <!-- </soft_contact> -->
  </gazebo>
  <gazebo reference="rbs-gripper_l_finger_link">
    <self_collide>1</self_collide>
    <!-- <soft_contact> -->
    <!--   <dart> -->
    <!--     <bone_attachment>100</bone_attachment> -->
    <!--     <stiffness>100</stiffness> -->
    <!--     <damping>10</damping> -->
    <!--     <flesh_mass_fraction>0.050000000000000003</flesh_mass_fraction> -->
    <!--   </dart> -->
    <!-- </soft_contact> -->
  </gazebo>
  <gazebo reference="rbs-gripper_r_finger_link">
    <self_collide>1</self_collide>
    <!-- <soft_contact> -->
    <!--   <dart> -->
    <!--     <bone_attachment>100</bone_attachment> -->
    <!--     <stiffness>100</stiffness> -->
    <!--     <damping>10</damping> -->
    <!--     <flesh_mass_fraction>0.050000000000000003</flesh_mass_fraction> -->
    <!--   </dart> -->
    <!-- </soft_contact> -->
  </gazebo>
</robot>
